Workbook

Sheet ENERO
C1: CLIENTE | G1: VEHICULO | M1: TRABAJO | R1: DATOS DE PAGO | X1: OT | Y1: PRODUCTO | Z1: COMISION
A2: FECHA | B2: OT | C2: NOMBRE | D2: RUT | E2: FONO | F2: CORREO | G2: MARCA | H2: MODELO | I2: KILOMETROS | J2: AÑO | K2: COLOR | L2: PATENTE | M2: ESCAPE | N2: REPRO | O2: IMPORT. | P2: OTROS | Q2: DETALLE | R2: RESERVA $25,000 | S2: TOTAL | T2: NETO | U2: COMISION | V2: Columna1 | X2: 3389 | Y2: SHAMPOO NEUTRO | Z2: 1000 | AB2: COMISIONES | AD2: VIATICOS | AE2: TOTAL
A3: 45662 | B3: 3382 | C3: BENJAMIN MORALES | D3: 21226116-5 | E3: 977830669 | F3: BMORALES@GMAIL.COM | G3: VW | H3: POLO | I3: 150000 | J3: 2012 | K3: PLATA | L3: DWRT52 | N3: X | Q3: REPRO STAGE 1 | R3: NO | S3: 549800 | T3: =S3/1.19 -> 462016.81 | U3: =Tabla1419[[#This Row],[NETO]]*2% -> 9240.3361 | Y3: SHAMPOO ACIDO | Z3: 1000 | AB3: ENERO | AC3: =U77 -> 725310.92 | AD3: 390969 | AE3: =AC3-AD3 -> 334341.92
A4: 45662 | B4: 3383 | C4: SEBASTIAN TOUMA | D4: 19671855-9 | E4: 967465571 | F4: SEBA.TOUMA@GMAIL.COM | G4: BMW | H4: 220I | I4: 1100 | J4: 2026 | K4: BLANCO | L4: VPWH83 | M4: X | P4: X | Q4: CATBACK + COLAS CROMO | R4: NO | S4: 749900 | T4: =S4/1.19 -> 630168.07 | U4: =Tabla1419[[#This Row],[NETO]]*2% -> 12603.361 | Y4: QUICK DETAILER | Z4: 1000 | AE4: =AE3 -> 334341.92
A5: 45662 | B5: 3384 | C5: BLAS VARGAS | D5: 19730664-5 | E5: 984994702 | F5: BLASVARGAS.MD@GMAIL.COM | G5: CHERY | H5: TIGGO 8 | I5: 6700 | J5: 2024 | K5: GRIS | L5: TVBF61 | N5: X | Q5: REPRO STAGE 1 | R5: NO | S5: 299900 | T5: =S5/1.19 -> 252016.81 | U5: =Tabla1419[[#This Row],[NETO]]*2% -> 5040.3361 | Y5: RENOVADOR NEUMATICOS | Z5: 1000
A6: 45662 | B6: 3385 | C6: AUTOMECANICA RVAL | D6: 76515620-3 | F6: RVAL@GMAIL.COM | G6: DATSUN | H6: 240SX | I6: 300000 | J6: 1990 | K6: BLANCO | Q6: CATBACK RESTAURACIÓN | R6: NO | S6: 450000 | T6: =S6/1.19 -> 378151.26 | U6: =Tabla1419[[#This Row],[NETO]]*2% -> 7563.0252 | X6: 3422 | Y6: RENOVADOR NEUMATICOS | Z6: 1000
A7: 45663 | B7: 3386 | C7: CRISTOBAL CABALLERO | D7: 19619493-2 | E7: 940967883 | F7: CRISTOBALCABALLEROZAMORA@GMAIL.COM | G7: FORD | H7: F150 | I7: 137000 | J7: 2018 | K7: BLANCO | L7: JYWG93 | M7: X | Q7: AXLE BACK SALIDA DOBLE COLAS NEGRAS | R7: SI | S7: 649900 | T7: =S7/1.19 -> 546134.45 | U7: =Tabla1419[[#This Row],[NETO]]*2% -> 10922.689 | Y7: SHAMPOO NEUTRO | Z7: 1000
A8: 45663 | B8: 3387 | C8: PÍETRO LOBOS | D8: 22173904-3 | E8: 956422768 | F8: PIETRO.LOBOS14@GMAIL.COM | G8: MERCEDES | H8: A200 | I8: 30000 | J8: 2021 | K8: BLANCO | L8: PBGT79 | P8: x | Q8: MANTENCIÓN | R8: NO | S8: 149900 | T8: =S8/1.19 -> 125966.39 | U8: =Tabla1419[[#This Row],[NETO]]*2% -> 2519.3277 | Y8: SHAMPOO HIDRO | Z8: 1000
A9: 45663 | B9: 3388 | C9: MATIAS URZUA | D9: 16646696-2 | E9: 957028836 | F9: MATI.URZUA@HOTMAIL.COM | G9: MERCEDES | H9: GLA200 | I9: 150000 | J9: 2015 | K9: NEGRO | L9: HDXY29 | P9: X | Q9: MANTENCIÓN 150.000 ACEITE, FILTRO ACEITE, POLEN Y AIRE REPARACIÓN DE ESCAPE | R9: NO | S9: 209600 | T9: =S9/1.19 -> 176134.45 | U9: =Tabla1419[[#This Row],[NETO]]*2% -> 3522.6891 | X9: 3425 | Y9: SHAMPOO HIDRO | Z9: 1000
A10: 45664 | B10: 3389 | C10: ABRAHAM MUÑOZ | D10: 20190004-2 | E10: 973390266 | F10: ABRHAHM1999XD@GMAIL.COM | G10: FORD | H10: MUSTANG GT | I10: 80000 | J10: 2015 | K10: ROJO | L10: HCLW94 | M10: X | Q10: REMOVER AMBOS SILENACIADORES | R10: SI | S10: 538600 | T10: =S10/1.19 -> 452605.04 | U10: =Tabla1419[[#This Row],[NETO]]*2% -> 9052.1008 | Z10: =SUM(Z2:Z9) -> 8000
A11: 45664 | B11: 3390 | C11: MARIO LARA | D11: 19890609-3 | E11: 982623350 | F11: MARIOSARMIENTO@1998@GMAIL.COM | G11: JAGUAR | H11: XJ | I11: 146000 | J11: 2007 | K11: NEGRO | L11: TW5265 | M11: X | Q11: MUFFLER DELETE | R11: NO | S11: 150000 | T11: =S11/1.19 -> 126050.42 | U11: =Tabla1419[[#This Row],[NETO]]*2% -> 2521.0084
A12: 45664 | B12: 3391 | C12: MATIAS VALENCIA | D12: 17729362-8 | E12: 982838400 | F12: MVALENCIA82@GMAIL.COM | G12: SUZUKI | H12: SWIFT | I12: 1000 | J12: 2026 | K12: AZUL | L12: VKTY44 | P12: X | Q12: INSTALACIÓN CATBACK REMUS | R12: NO | S12: 150000 | T12: =S12/1.19 -> 126050.42 | U12: =Tabla1419[[#This Row],[NETO]]*2% -> 2521.0084
A13: 45664 | B13: 3392 | C13: BORIS QUIROZ | D13: 19744905-5 | E13: 991097691 | F13: BQUIROZST8@GMAIL.COM | G13: FORD | H13: EXPLORER | I13: 10000 | J13: 2025 | K13: AZUL | Q13: AXLE BACK FREE MAS COLAS NEGRAS DOBLES 4" | R13: NO | S13: 449900 | T13: =S13/1.19 -> 378067.23 | U13: =Tabla1419[[#This Row],[NETO]]*2% -> 7561.3445
A14: 45664 | B14: 3393 | C14: JAVIER LUNA | D14: 19484521-9 | E14: 995917922 | F14: JAVIER.LUNA@USACH.CL | G14: VW | H14: GOLF | I14: 114032 | J14: 2015 | K14: BLANCO | L14: GHPX96 | P14: X | Q14: MANTENCIÓN + CAMBIO ACEITE + FILTRO ACEITE + FILTRO POLEN | R14: SI | S14: 128800 | T14: =S14/1.19 -> 108235.29 | U14: =Tabla1419[[#This Row],[NETO]]*2% -> 2164.7059
A15: 45665 | B15: 3394 | C15: TRANSPORTES LS | D15: 76704181-0 | E15: 998174044 | F15: TRANSPORTESLS@GMAIL.COM | G15: FORD | H15: RANGER RAPTOR | I15: 2000 | J15: 2026 | K15: GRIS | L15: VRDF71 | Q15: LINEA + BMC + BUJIAS | R15: SI | S15: 2584700 | T15: =S15/1.19 -> 2172016.8 | U15: =Tabla1419[[#This Row],[NETO]]*2% -> 43440.336
A16: 45665 | B16: 3395 | C16: MATIAS VALENCIA | D16: 17729362-8 | E16: 982838400 | F16: MVALENCIA82@GMAIL.COM | G16: SUZUKI | H16: SWIFT | I16: 2500 | J16: 2026 | K16: AZUL | L16: VKTY44 | M16: X | Q16: INSTALACIÓN DOWNPIPE | R16: NO | S16: 185000 | T16: =S16/1.19 -> 155462.18 | U16: =Tabla1419[[#This Row],[NETO]]*2% -> 3109.2437
A17: 45665 | B17: 3396 | C17: VICENTE CONTRERAS | D17: 21294072-0 | E17: 982515841 | F17: VICHOCONTRERAS3@GMAIL.COM | G17: MERCEDES | H17: A250 | I17: 74000 | J17: 2018 | K17: PLATA | L17: KLBW45 | M17: X | Q17: CUT-OUT MAS CONTROL | R17: NO | S17: 450000 | T17: =S17/1.19 -> 378151.26 | U17: =Tabla1419[[#This Row],[NETO]]*2% -> 7563.0252
A18: 45666 | B18: 3397 | C18: GONZALO QUIROZ | D18: 16702409-3 | E18: 983877803 | F18: GONZALO.QUIROZ.C@GMAIL.COM | G18: FORD | H18: F150 | I18: 80000 | J18: 2019 | K18: BLANCO | L18: LBTK53 | P18: X | Q18: CUT-OUT DB-KILLER | R18: NO | S18: 430000 | T18: =S18/1.19 -> 361344.54 | U18: =Tabla1419[[#This Row],[NETO]]*2% -> 7226.8908
A19: 45666 | B19: 3398 | C19: MATIAS URZUA | D19: 16646696-2 | E19: 957028836 | F19: MATI.URZUA@HOTMAIL.COM | G19: MERCEDES | H19: GLA200 | I19: 150000 | J19: 2015 | K19: NEGRO | L19: HDXY29 | P19: x | Q19: SPRINTBOOSTER | R19: NO | S19: 279900 | T19: =S19/1.19 -> 235210.08 | U19: =Tabla1419[[#This Row],[NETO]]*2% -> 4704.2017
A20: 45669 | B20: 3399 | C20: AQUILES CASTRO | D20: 21412786-5 | E20: 997576549 | F20: AKI.EXZUQUIEL@GMAIL.COM | G20: MAZDA | H20: MX5 | I20: 39700 | J20: 2023 | K20: GRIS | L20: SKZT99 | M20: X | Q20: MULTIPLES POPS Y REPRO | R20: NO | S20: 1100000 | T20: =S20/1.19 -> 924369.75 | U20: =Tabla1419[[#This Row],[NETO]]*2% -> 18487.395
A21: 46034 | B21: 3400 | C21: DIESEL TUNING | D21: 76319264-4 | E21: 988298131 | G21: MINI | H21: COOPER S | I21: 95000 | J21: 2014 | K21: BLANCO | L21: GWXL83 | M21: X | Q21: CAMBIO SILENCIADOR POR WICKED FLOW | R21: NO | S21: 385000 | T21: =S21/1.19 -> 323529.41 | U21: =Tabla1419[[#This Row],[NETO]]*2% -> 6470.5882
A22: 46034 | B22: 3401 | C22: DIEGO ORDENES | D22: 16977905-8 | E22: 993192710 | F22: DIEGO.ORDENES@HOTMAIL.COM | G22: CHEVROLET | H22: SILVERADO | I22: 237631 | J22: 1997 | K22: CELESTE | L22: SB8121 | P22: X | Q22: CAMBIO BUJIAS | R22: NO | S22: 128900 | T22: =S22/1.19 -> 108319.33 | U22: =Tabla1419[[#This Row],[NETO]]*2% -> 2166.3866
A23: 46034 | B23: 3402 | C23: BERNARDO FERNANDEZ | D23: 17704229-3 | E23: 978393986 | F23: BFERNEANDEZ13@GMAIL.COM | G23: MITSUBISHI | H23: LANCER | I23: 200000 | J23: 1998 | K23: BLANCO | M23: X | Q23: REPARACIÓN DE MULTIPLE | R23: NO | S23: 160000 | T23: =S23/1.19 -> 134453.78 | U23: =Tabla1419[[#This Row],[NETO]]*2% -> 2689.0756
A24: 46034 | B24: 3403 | C24: MARTIN MOYA | D24: 20392484-4 | E24: 978872240 | F24: MARTINDBHW18@GMAIL.COM | G24: FORD | H24: MAVERICK | I24: 31000 | J24: 2024 | K24: AZUL | L24: TKCV74 | M24: X | Q24: REPRO STAGE 1 | R24: SI | S24: 349900 | T24: =S24/1.19 -> 294033.61 | U24: =Tabla1419[[#This Row],[NETO]]*2% -> 5880.6723
A25: 46035 | B25: 3404 | C25: JOAQUIN RENDIC | D25: 19245541-3 | E25: 940894533 | F25: JOACO.OLIVOS1@GMAIL.COM | G25: BMW | H25: M4 | I25: 49000 | J25: 2018 | K25: NEGRO | L25: JXXC30 | M25: X | Q25: AXLE BACK | R25: NO | S25: 1499900 | T25: =S25/1.19 -> 1260420.2 | U25: =Tabla1419[[#This Row],[NETO]]*2% -> 25208.403
A26: 46035 | B26: 3405 | C26: KAUFMANN | G26: MERCEDES | H26: G800 | I26: 10000 | J26: 2025 | K26: NEGRO | L26: TVVL50 | M26: X | Q26: REPARACION VALVULAS ESCAPE | R26: NO | S26: 599900 | T26: =S26/1.19 -> 504117.65 | U26: =Tabla1419[[#This Row],[NETO]]*2% -> 10082.353
A27: 46035 | B27: 3406 | C27: KAUFMANN | G27: MERCEDES | H27: A35S | I27: 10000 | J27: 2023 | K27: GRIS | L27: SPBS97 | M27: X | Q27: REPARACIÓN LINEA MAS VALVULAS | R27: NO | S27: 919900 | T27: =S27/1.19 -> 773025.21 | U27: =Tabla1419[[#This Row],[NETO]]*2% -> 15460.504
A28: 46035 | B28: 3407 | C28: TRANSPORTES LS | D28: 76704181-0 | E28: 998174044 | F28: TRANSPORTESLS@GMAIL.COM | G28: RAM | H28: 2500 | I28: 40000 | J28: 2026 | K28: PLATA | L28: SLRR67 | Q28: 7290000 DPF Y EGR OFF BULLY DOG ECU NUEVA | R28: NO | S28: 1100000 | T28: =S28/1.19 -> 924369.75 | U28: =Tabla1419[[#This Row],[NETO]]*2% -> 18487.395
A29: 46035 | B29: 3408 | C29: LUIS FERREIRA | D29: 6613642-6 | E29: 950804086 | F29: LFERREIRA@GMAIL.COM | G29: VW | H29: COMBI | I29: 200000 | J29: 1975 | K29: BLANCO | L29: AA2222 | M29: X | Q29: SILENCIADOR A MEDIDA MAS ESCAPE | R29: NO | S29: 350000 | T29: =S29/1.19 -> 294117.65 | U29: =Tabla1419[[#This Row],[NETO]]*2% -> 5882.3529
A30: 46035 | B30: 3409 | C30: DASSEN | D30: 77537871-9 | E30: 987670659 | F30: DASSENINVERSIONES@GMAIL.COM | G30: VW | H30: TIGUAN | I30: 90000 | J30: 2019 | K30: BLANCA | L30: AA1111 | P30: X | Q30: VENTA COLAS 4" DOBLE | R30: NO | S30: 249900 | T30: =S30/1.19 -> 210000 | U30: =Tabla1419[[#This Row],[NETO]]*2% -> 4200
A31: 46036 | B31: 3410 | C31: JUAN ARAYA | D31: 15745527-3 | E31: 982557266 | F31: JARAYA21@GMAIL | G31: JEEP | H31: GRAND CHEROKEE | I31: 182000 | J31: 2015 | K31: NEGRO | L31: GXGB88 | M31: X | Q31: X-PIPE + SILENCIADOR ALTO FLUJO VALVETRONIC + COLAS 4" CROMO | R31: NO | S31: 1600000 | T31: =S31/1.19 -> 1344537.8 | U31: =Tabla1419[[#This Row],[NETO]]*2% -> 26890.756
A32: 45672 | B32: 3411 | C32: SEBASTIAN SALINAS | D32: 77152386-2 | E32: 984043940 | F32: purificadorasnamiguel930@gmail.com | G32: BMW | H32: 540 | I32: 83000 | J32: 2018 | K32: GRIS | L32: KFXS81 | M32: X | N32: X | Q32: DOWNPIPE + PROTECCIÓN TERMICA + REPRO STAGE 2 + BUJIAS -1 GRADO | R32: NO | S32: 1150000 | T32: =S32/1.19 -> 966386.55 | U32: =Tabla1419[[#This Row],[NETO]]*2% -> 19327.731
A33: 46038 | B33: 3412 | C33: NIBALDO ARANCIBIA | D33: 19588338-6 | E33: 962048770 | F33: NIBALDOARANCIBIA2@GMAIL.COM | G33: MERCEDES | H33: A200 | I33: 153000 | J33: 2017 | K33: BLANCO | L33: JRWH18 | M33: X | Q33: CUT-OUT MAS CONTROL REMOTO | R33: SI | S33: 449900 | T33: =S33/1.19 -> 378067.23 | U33: =Tabla1419[[#This Row],[NETO]]*2% -> 7561.3445
A34: 46038 | B34: 3413 | C34: JUAN MUÑOZ | D34: 78278577-K | E34: 998837086 | F34: JMUÑOZ@GMAIL.COM | G34: FORD | H34: F150 | I34: 60000 | J34: 2024 | K34: BLANCO | L34: STXH86 | M34: X | Q34: CUT-OUT SPRINTBOOSTER + BMC | R34: NO | S34: 859700 | T34: =S34/1.19 -> 722436.97 | U34: =Tabla1419[[#This Row],[NETO]]*2% -> 14448.739
A35: 46038 | B35: 3414 | C35: TOMAS MONROY | D35: 21199168-2 | E35: 969178676 | F35: TOMAS.MONROY.RAMIREZ@GMAIL.COM | G35: VW | H35: SCIROCCO | I35: 75000 | J35: 2018 | K35: BLANCO | L35: KSXS32 | M35: X | Q35: CUT OUT MAS CONTROL | R35: SI | S35: 449900 | T35: =S35/1.19 -> 378067.23 | U35: =Tabla1419[[#This Row],[NETO]]*2% -> 7561.3445
A36: 46041 | B36: 3415 | C36: GABRIEL PONCE | D36: 26213430 | E36: 5492664301288 | F36: PONCEMGABRIEL@GMAIL.COM | G36: AUDI | H36: A7 | I36: 49000 | J36: 2017 | K36: PLATA | M36: X | Q36: DOBLE CUT OUT MAS MUFFLER DELETE | R36: SI | S36: 1009900 | T36: =S36/1.19 -> 848655.46 | U36: =Tabla1419[[#This Row],[NETO]]*2% -> 16973.109
A37: 45676 | B37: 3416 | C37: FRANCISCO BOBADILLA | D37: 18220313-0 | E37: 944903816 | F37: FRANCISCO.BYP@GMAIL.COM | G37: JEEP | H37: GRAND CHEROKEE | I37: 55000 | J37: 2022 | K37: BLANCO | L37: RGTW60 | M37: X | Q37: LINEA COMPLETAS MAS VALVETRONIC MAS 1 CONTROL COLAS CROMO | R37: SI | S37: 2100000 | T37: =S37/1.19 -> 1764705.9 | U37: =Tabla1419[[#This Row],[NETO]]*2% -> 35294.118
A38: 46041 | B38: 3417 | C38: SEBASTIAN AGUIRRE | D38: 18298095-1 | E38: 975291632 | F38: SAGUIRREBERNAL@GMAIL.COM | G38: BMW | H38: M235 | I38: 49000 | J38: 2021 | K38: AZUL | L38: PKTT10 | M38: X | Q38: CATBACK MAS SILENCIADOR ALTO FLUJO WICKED FLOW COLAS NEGRAS | R38: SI | S38: 849000 | T38: =S38/1.19 -> 713445.38 | U38: =Tabla1419[[#This Row],[NETO]]*2% -> 14268.908
A39: 46041 | B39: 3418 | C39: MATIAS CARVAJAL | D39: 14255675-2 | E39: 964866880 | F39: MCARVAJAL12@GMAIL.COM | G39: HYUNDAI | H39: GENESIS | I39: 130000 | J39: 2012 | K39: ROJO | L39: HG3131 | P39: X | Q39: INSPECCIÓN | R39: NO | S39: 25000 | T39: =S39/1.19 -> 21008.403 | U39: =Tabla1419[[#This Row],[NETO]]*2% -> 420.16807
A40: 46041 | B40: 3419 | C40: SIMON ALVAREZ | D40: 19112927-K | E40: 976370656 | F40: SLAVAREZ21@GMAIL.COM | G40: FIAT | H40: BRAVO | I40: 120000 | J40: 2010 | K40: BLANCO | L40: FTBR19 | P40: X | Q40: RECUBRIMIENTO TERMICO MULTIPLE TURBO Y MODIFICAR MULTIPLE | R40: NO | S40: 304900 | T40: =S40/1.19 -> 256218.49 | U40: =Tabla1419[[#This Row],[NETO]]*2% -> 5124.3697
...

Sheet FEBRERO
C1: CLIENTE | G1: VEHICULO | M1: TRABAJO | R1: DATOS DE PAGO | X1: OT | Y1: PRODUCTO | Z1: COMISION
A2: FECHA | B2: OT | C2: NOMBRE | D2: RUT | E2: FONO | F2: CORREO | G2: MARCA | H2: MODELO | I2: KILOMETROS | J2: AÑO | K2: COLOR | L2: PATENTE | M2: ESCAPE | N2: REPRO | O2: IMPORT. | P2: OTROS | Q2: DETALLE | R2: RESERVA $25,000 | S2: TOTAL | T2: NETO | U2: COMISION
A3: 46055 | B3: 3449 | C3: EMILIO | D3: 26611680-2 | E3: 998220688 | G3: MAZDA | H3: MAZDA 6 | I3: 23000 | J3: 2018 | K3: GRIS | L3: KHCF39 | M3: X | Q3: AXLE BACK | R3: NO | S3: 449900 | T3: =S3/1.19 -> 378067.23 | U3: =Tabla141921[[#This Row],[NETO]]*2% -> 7561.3445
A4: 46055 | B4: 3450 | C4: CLAUDIO | D4: 77567117-3 | E4: 956379889 | F4: CLAUDIO.GOMEZ@SEGGEC.CL | G4: FORD | H4: F150 | I4: 1000 | J4: 2026 | K4: GRIS | L4: VTFP77 | M4: X | Q4: CUT-OUT | R4: NO | S4: 449900 | T4: =S4/1.19 -> 378067.23 | U4: =Tabla141921[[#This Row],[NETO]]*2% -> 7561.3445
A5: 46055 | B5: 3451 | C5: GABRIEL VALDERRAMA | D5: 10837808-4 | E5: 945629251 | F5: GVDRR342@GMAIL.COM | G5: BMW | H5: 120i | I5: 50000 | J5: 2018 | K5: GRIS | L5: JKHT66 | M5: X | Q5: DOWNPIPE | R5: SI | S5: 389900 | T5: =S5/1.19 -> 327647.06 | U5: =Tabla141921[[#This Row],[NETO]]*2% -> 6552.9412
A6: 46055 | B6: 3452 | C6: NICOLAS RIQUELME | D6: 18308797-5 | E6: 979687731 | F6: NICOLASRIQUELME12@GMAIL.COM | G6: BMW | H6: 525 E34 | I6: 185000 | J6: 1990 | K6: GRIS | L6: EX6782 | M6: X | Q6: REPARACIÓN ESCAPE | R6: NO | S6: 120000 | T6: =S6/1.19 -> 100840.34 | U6: =Tabla141921[[#This Row],[NETO]]*2% -> 2016.8067
A7: 46056 | B7: 3453 | C7: ALEXANDER SALAZAR | D7: 21236741-9 | E7: 944306244 | F7: ALEXANDERSALAZAR088@GMAIL.COM | G7: VW | H7: POLO | I7: 7600 | J7: 2025 | K7: PLATA | L7: VHRW61 | P7: X | Q7: MODIFIC | R7: NO | S7: 75000 | T7: =S7/1.19 -> 63025.21 | U7: =Tabla141921[[#This Row],[NETO]]*2% -> 1260.5042
A8: 46057 | B8: 3454 | C8: IGNACIO MORAES | D8: 20427704-4 | E8: 965729979 | F8: IGNAMOREDENZ@GMAIL.COM | G8: AUDI | H8: A3 | I8: 120000 | J8: 2018 | K8: GRIS | L8: JLDW33 | M8: X | Q8: AXLE BACK FREE CON COLAS NUEVAS 3.5" CROMO | R8: SI | S8: 356800 | T8: =S8/1.19 -> 299831.93 | U8: =Tabla141921[[#This Row],[NETO]]*2% -> 5996.6387
A9: 46057 | B9: 3455 | C9: LUIS PLAZA | D9: 17079053-7 | E9: 959016781 | F9: EDUARDOPLAZA21@GMAIL.COM | G9: SUZUKI | H9: GRAND VITARA | I9: 104000 | J9: 2018 | K9: GRIS | L9: KSWS45 | M9: X | Q9: AXLE BACK SILENCIADOR ALTO FLUJO MAS CUT OUT | R9: SI | S9: 319900 | T9: =S9/1.19 -> 268823.53 | U9: =Tabla141921[[#This Row],[NETO]]*2% -> 5376.4706
A10: 46057 | B10: 3456 | C10: BRYAN SAN MARTIN | D10: 18848449-2 | E10: 961916599 | F10: BRSANMARTIN@GMAIL.COM | G10: VW | H10: AMAROK | I10: 281606 | J10: 2012 | K10: BLANCO | L10: DFLK65 | M10: X | Q10: REPARACIÓN ESCAPE | R10: NO | S10: 60000 | T10: =S10/1.19 -> 50420.168 | U10: =Tabla141921[[#This Row],[NETO]]*2% -> 1008.4034 | Z10: =SUM(Z2:Z9) -> 0
A11: 46057 | B11: 3457 | C11: INVERSIONES ACR | D11: 76797593-7 | E11: DESPACHO | F11: DESPACHO | G11: BORLA | H11: BORLA | I11: BORLA | J11: 2012 | K11: CROMO | L11: BORLA | P11: X | Q11: DESPACHO | R11: NO | S11: 219900 | T11: =S11/1.19 -> 184789.92 | U11: =Tabla141921[[#This Row],[NETO]]*2% -> 3695.7983
A12: 46057 | B12: 3458 | C12: PABLO VARGAS | D12: 16938083-K | E12: 954348547 | G12: MERCEDES | H12: A250 | I12: 160000 | J12: 2019 | K12: BLANCO | L12: BLANCO | P12: X | Q12: MANTENCION MARIPOSA | R12: NO | S12: 45000 | T12: =S12/1.19 -> 37815.126 | U12: =Tabla141921[[#This Row],[NETO]]*2% -> 756.30252
A13: 46057 | B13: 3459 | C13: JM&H CONSTRUCCIONES SPA | D13: 77657779-0 | E13: 967271587 | F13: PABLOHEREDI75@GMAIL.COM | G13: FORD | H13: F150 | I13: 218802 | J13: 2012 | K13: AZUL | L13: DRKZ58 | N13: X | Q13: FALTA CARGAR MAPA | R13: NO | S13: 499900 | T13: =S13/1.19 -> 420084.03 | U13: =Tabla141921[[#This Row],[NETO]]*2% -> 8401.6807
A14: 46058 | B14: 3460 | C14: VLADIMIR MENESES | D14: 21009150-5 | E14: 948497583 | F14: VLADIMIRMENSESTP@GMAIL.COM | G14: DODGE | H14: CHALLENGER | I14: 18000 | J14: 2014 | K14: AZUL | L14: GBDT66 | M14: X | Q14: CATBACK + REPRO | R14: SI | S14: 1299900 | T14: =S14/1.19 -> 1092352.9 | U14: =Tabla141921[[#This Row],[NETO]]*2% -> 21847.059
A15: 46059 | B15: 3461 | C15: RODRIGO BENAVIDES | D15: 17231800-2 | E15: 944546921 | F15: RODRIGOBENAVUDES@GMAIL.COM | G15: JEEP | H15: WRANGLER | I15: 58000 | J15: 2021 | K15: GRIS | L15: PKJD67 | M15: X | Q15: CATBACK CON VALVETRONIC MAS SPRINTBOOSTER Y ALTO FLUO BMC | R15: SI | S15: 1709700 | T15: =S15/1.19 -> 1436722.7 | U15: =Tabla141921[[#This Row],[NETO]]*2% -> 28734.454
A16: 46059 | B16: 3462 | C16: SEBASTIAN ESCARATE | E16: 944062849 | G16: FORD | H16: ESCAPE | I16: 130000 | J16: 2018 | K16: BLANCO | L16: KPFH86 | N16: X | Q16: REPRO STAGE 1 | R16: SI | S16: 299900 | T16: =S16/1.19 -> 252016.81 | U16: =Tabla141921[[#This Row],[NETO]]*2% -> 5040.3361
A17: 46059 | B17: 3463 | C17: TRANSPORTES LS | D17: 76704181-0 | E17: 998174044 | F17: TRANSPORTESLS@GMAIL.COM | G17: RAM | H17: 2500 | I17: 18000 | J17: 2023 | K17: BLANCO | L17: RWWZ45 | M17: X | N17: X | Q17: BULLY DOG CAMBIO DE ECU, CATBACK + CHERRY BOMB | R17: SI | S17: 7100000 | T17: =S17/1.19 -> 5966386.6 | U17: =Tabla141921[[#This Row],[NETO]]*2% -> 119327.73
A18: 46059 | B18: 3464 | C18: JM&H CONSTRUCCIONES SPA | D18: 77657779-0 | E18: 967271587 | F18: PABLOHEREDI75@GMAIL.COM | G18: FORD | H18: F150 | I18: 218802 | J18: 2012 | K18: AZUL | L18: DRKZ58 | M18: X | Q18: CAMBIO DE SILENCIADOR ORIGINAL POR WICKED FLOW KAMIKAZE | R18: SI | S18: 349900 | T18: =S18/1.19 -> 294033.61 | U18: =Tabla141921[[#This Row],[NETO]]*2% -> 5880.6723
A19: 46062 | B19: 3465 | C19: AXEL LIZANA | D19: 20974672-7 | E19: 972244655 | F19: AXELYERKO12@GMAIL.COM | G19: VOLVO | H19: V40 | I19: 81000 | J19: 2013 | K19: BLANCO | L19: FLKF96 | N19: X | Q19: REPRO STAGE 1 | R19: SI | S19: 319900 | T19: =S19/1.19 -> 268823.53 | U19: =Tabla141921[[#This Row],[NETO]]*2% -> 5376.4706
A20: 46062 | B20: 3466 | C20: MATIAS GONZALEZ | D20: 19410422-7 | E20: 963212823 | F20: GOZALEZ.IGMATIAS@GMAIL.COM | G20: CUPRA | H20: FORMENTOR VZ | I20: 30000 | J20: 2023 | K20: BLANCO | L20: STXG25 | M20: X | Q20: CUT-OUT MAS CONTROL | R20: SI | S20: 449900 | T20: =S20/1.19 -> 378067.23 | U20: =Tabla141921[[#This Row],[NETO]]*2% -> 7561.3445
A21: 46062 | B21: 3467 | C21: TRANS CARLOS ESCOBAR | D21: 77083984-K | G21: FORD | H21: F150 | I21: 20000 | J21: 2023 | K21: AZUL | L21: SYKH95 | M21: X | Q21: CATBACK MAS SALIDA DOBLE Y COLAS NEGRAS | R21: NO | S21: 1499900 | T21: =S21/1.19 -> 1260420.2 | U21: =Tabla141921[[#This Row],[NETO]]*2% -> 25208.403
A22: 46063 | B22: 3468 | C22: FRANCISCO FUENTES | D22: 77702651-8 | E22: 994376132 | F22: FFUENTES@BLINDAJESCHILE.COM | G22: PORSCHE | H22: CAYENNE S | I22: 34 | J22: 2026 | K22: AZUL | L22: VTVY41 | P22: X | Q22: AXLE BACK MAS COLAS NUEVAS MAS MUFFLER DELETE | R22: SI | S22: 1399900 | T22: =S22/1.19 -> 1176386.6 | U22: =Tabla141921[[#This Row],[NETO]]*2% -> 23527.731
A23: 46064 | B23: 3469 | C23: BLAS VARGAS | D23: 19730664-5 | E23: 984994702 | F23: BLASVARGAS.MD@GMAIL.COM | G23: CHERY | H23: TIGGO 8 | I23: 8700 | J23: 2025 | K23: GRIS | L23: TVBF61 | P23: X | Q23: MANTENCIÓN 8700 KMS | R23: NO | S23: 99900 | T23: =S23/1.19 -> 83949.58 | U23: =Tabla141921[[#This Row],[NETO]]*2% -> 1678.9916
A24: 46065 | B24: 3470 | C24: LUIS FELIPE GUTIERREZ | D24: 19130440-3 | E24: 992650008 | F24: LUISGUTIERREZESPINDOLA@GMAIL.COM | G24: SUBARU | H24: WRX | I24: 22000 | J24: 2023 | K24: BLANCO | L24: SGSF99 | M24: X | Q24: LINEA COMPLETA MAS SILENCIADOR ALTO FLUJO WICKED Y COLAS NUEVAS DOBLES CROMO | R24: SI | S24: 819900 | T24: =S24/1.19 -> 688991.6 | U24: =Tabla141921[[#This Row],[NETO]]*2% -> 13779.832
A25: 46065 | B25: 3471 | C25: FRANCISCO MUÑOZ | D25: 18632177-4 | E25: 989337523 | F25: FMUÑOZ@GMAIL.COM | G25: CHEVROLET | H25: SILVERADO | I25: 125000 | J25: 2019 | K25: GRIS | L25: KZGH22 | M25: X | Q25: REEINSTALACIÓN SILENCIADOR ALTO FLUJO WICKED FLOW | R25: NO | S25: 150000 | T25: =S25/1.19 -> 126050.42 | U25: =Tabla141921[[#This Row],[NETO]]*2% -> 2521.0084
A26: 46065 | B26: 3472 | C26: JORDANO CID | D26: 12386675-4 | E26: 982407526 | G26: CHEVROLET | H26: SILVERADO | I26: 20000 | J26: 2025 | K26: NEGRO | L26: TZHL10 | M26: X | Q26: COLAS DOBLES FIBRA DE CARBONO | R26: SI | S26: 599900 | T26: =S26/1.19 -> 504117.65 | U26: =Tabla141921[[#This Row],[NETO]]*2% -> 10082.353
A27: 46066 | B27: 3473 | C27: AGUSTIN MIRANDA | D27: 22138467-9 | E27: 959112792 | F27: AGUSTINMIHA@GMAIL.COM | G27: HONDA | H27: CIVIC | I27: 86000 | J27: 2017 | K27: BLANCO | L27: JKPV59 | M27: X | Q27: CUT-OUT MAS CONTROL | R27: SI | S27: 629900 | T27: =S27/1.19 -> 529327.73 | U27: =Tabla141921[[#This Row],[NETO]]*2% -> 10586.555
A28: 46066 | B28: 3474 | C28: MATIAS FURLONG | E28: 950002694 | F28: MATIASFUR@GMAIL.COM | G28: JEEP | H28: GRAND CHEROKEE | I28: 200000 | J28: 2009 | K28: NEGRO | L28: BSGJ33 | M28: X | Q28: CAMBIO SILENCIADOR Y COLA | R28: SI | S28: 1050000 | T28: =S28/1.19 -> 882352.94 | U28: =Tabla141921[[#This Row],[NETO]]*2% -> 17647.059
A29: 46066 | B29: 3475 | C29: MARCOS VILCHES | D29: 16924870-2 | E29: 990160213 | F29: MARCOS.VILCHES32@GMAIL.COM | G29: FIAT | H29: FIORINO CITY | I29: 250000 | J29: 2015 | K29: BLANCO | L29: HDVW46 | M29: X | Q29: REPRO DESACTIVACIÓN | R29: NO | S29: 150000 | T29: =S29/1.19 -> 126050.42 | U29: =Tabla141921[[#This Row],[NETO]]*2% -> 2521.0084
A30: 46066 | B30: 3476 | C30: IÑIGO OVALLE | D30: 21502388-5 | E30: 951328844 | F30: IINIGOOVALLE@GMAIL.COM | G30: AUDI | H30: A3 | I30: 113000 | J30: 2017 | K30: GRIS | L30: JVRX10 | M30: X | Q30: CUT-OUT MAS CONTROL REMOTO | R30: SI | S30: 449900 | T30: =S30/1.19 -> 378067.23 | U30: =Tabla141921[[#This Row],[NETO]]*2% -> 7561.3445
T31: =S31/1.19 -> 0 | U31: =Tabla141921[[#This Row],[NETO]]*2% -> 0
T32: =S32/1.19 -> 0 | U32: =Tabla141921[[#This Row],[NETO]]*2% -> 0
T33: =S33/1.19 -> 0 | U33: =Tabla141921[[#This Row],[NETO]]*2% -> 0
T34: =S34/1.19 -> 0 | U34: =Tabla141921[[#This Row],[NETO]]*2% -> 0
T35: =S35/1.19 -> 0 | U35: =Tabla141921[[#This Row],[NETO]]*2% -> 0
T36: =S36/1.19 -> 0 | U36: =Tabla141921[[#This Row],[NETO]]*2% -> 0
T37: =S37/1.19 -> 0 | U37: =Tabla141921[[#This Row],[NETO]]*2% -> 0
T38: =S38/1.19 -> 0 | U38: =Tabla141921[[#This Row],[NETO]]*2% -> 0
T39: =S39/1.19 -> 0 | U39: =Tabla141921[[#This Row],[NETO]]*2% -> 0
T40: =S40/1.19 -> 0 | U40: =Tabla141921[[#This Row],[NETO]]*2% -> 0
...

Sheet MARZO
C1: CLIENTE | G1: VEHICULO | M1: TRABAJO | R1: DATOS DE PAGO | X1: OT | Y1: PRODUCTO | Z1: COMISION
A2: FECHA | B2: OT | C2: NOMBRE | D2: RUT | E2: FONO | F2: CORREO | G2: MARCA | H2: MODELO | I2: KILOMETROS | J2: AÑO | K2: COLOR | L2: PATENTE | M2: ESCAPE | N2: REPRO | O2: IMPORT. | P2: OTROS | Q2: DETALLE | R2: RESERVA $25,000 | S2: TOTAL | T2: NETO | U2: COMISION
T3: =S3/1.19 -> 0 | U3: =Tabla141923[[#This Row],[NETO]]*2% -> 0
T4: =S4/1.19 -> 0 | U4: =Tabla141923[[#This Row],[NETO]]*2% -> 0
A5: 46083 | B5: 3477 | C5: MIGUEL PALMA | D5: 18375904-3 | E5: 951705661 | F5: MIGUELLPALMAG@GMAIL.COM | G5: BMW | H5: 240 M | I5: 30000 | J5: 2023 | K5: MORADO | L5: RXYK24 | M5: X | Q5: CATBACK + VALVETRONIC + COLAS DOBLES 4" | R5: SI | S5: 1399900 | T5: =S5/1.19 -> 1176386.6 | U5: =Tabla141923[[#This Row],[NETO]]*2% -> 23527.731
A6: 46083 | B6: 3478 | C6: JUAN PABLO OSSA | D6: 7003083-7 | E6: 992329074 | F6: JPOSSA@FRUCITRUS.COM | G6: CHEVROLET | H6: TAHOE | I6: 21500 | J6: 2026 | K6: PLATA | L6: VHTG99 | M6: X | Q6: CUT-OUT MAS CONTROL | R6: NO | S6: 449900 | T6: =S6/1.19 -> 378067.23 | U6: =Tabla141923[[#This Row],[NETO]]*2% -> 7561.3445
B7: 3479 | T7: =S7/1.19 -> 0 | U7: =Tabla141923[[#This Row],[NETO]]*2% -> 0
B8: 3480 | T8: =S8/1.19 -> 0 | U8: =Tabla141923[[#This Row],[NETO]]*2% -> 0
B9: 3481 | T9: =S9/1.19 -> 0 | U9: =Tabla141923[[#This Row],[NETO]]*2% -> 0
B10: 3482 | T10: =S10/1.19 -> 0 | U10: =Tabla141923[[#This Row],[NETO]]*2% -> 0 | Z10: =SUM(Z2:Z9) -> 0
B11: 3483 | T11: =S11/1.19 -> 0 | U11: =Tabla141923[[#This Row],[NETO]]*2% -> 0
B12: 3484 | T12: =S12/1.19 -> 0 | U12: =Tabla141923[[#This Row],[NETO]]*2% -> 0
B13: 3485 | T13: =S13/1.19 -> 0 | U13: =Tabla141923[[#This Row],[NETO]]*2% -> 0
B14: 3486 | T14: =S14/1.19 -> 0 | U14: =Tabla141923[[#This Row],[NETO]]*2% -> 0
B15: 3487 | T15: =S15/1.19 -> 0 | U15: =Tabla141923[[#This Row],[NETO]]*2% -> 0
B16: 3488 | T16: =S16/1.19 -> 0 | U16: =Tabla141923[[#This Row],[NETO]]*2% -> 0
B17: 3489 | T17: =S17/1.19 -> 0 | U17: =Tabla141923[[#This Row],[NETO]]*2% -> 0
B18: 3490 | T18: =S18/1.19 -> 0 | U18: =Tabla141923[[#This Row],[NETO]]*2% -> 0
B19: 3491 | T19: =S19/1.19 -> 0 | U19: =Tabla141923[[#This Row],[NETO]]*2% -> 0
B20: 3492 | T20: =S20/1.19 -> 0 | U20: =Tabla141923[[#This Row],[NETO]]*2% -> 0
B21: 3493 | T21: =S21/1.19 -> 0 | U21: =Tabla141923[[#This Row],[NETO]]*2% -> 0
B22: 3494 | T22: =S22/1.19 -> 0 | U22: =Tabla141923[[#This Row],[NETO]]*2% -> 0
... B49: 3521 | T49: =S49/1.19 -> 0 | U49: =Tabla141923[[#This Row],[NETO]]*2% -> 0
A50: TOTAL | B50: =COUNT(B3:B49) -> 45 | S50: =SUM(S3:S49) -> 1849800 | T50: =SUM(T3:T49) -> 1554453.8 | U50: =Tabla141923[[#This Row],[NETO]]*2% -> 31089.076

Sheet ABRIL
C1: CLIENTE | G1: VEHICULO | M1: TRABAJO | R1: DATOS DE PAGO | X1: OT | Y1: PRODUCTO | Z1: COMISION
A2: FECHA | B2: OT | C2: NOMBRE | D2: RUT | E2: FONO | F2: CORREO | G2: MARCA | H2: MODELO | I2: KILOMETROS | J2: AÑO | K2: COLOR | L2: PATENTE | M2: ESCAPE | N2: REPRO | O2: IMPORT. | P2: OTROS | Q2: DETALLE | R2: RESERVA $25,000 | S2: TOTAL | T2: NETO | U2: COMISION
T3: =S3/1.19 -> 0 | U3: =Tabla141925[[#This Row],[NETO]]*2% -> 0
T4: =S4/1.19 -> 0 | U4: =Tabla141925[[#This Row],[NETO]]*2% -> 0
T5: =S5/1.19 -> 0 | U5: =Tabla141925[[#This Row],[NETO]]*2% -> 0
T6: =S6/1.19 -> 0 | U6: =Tabla141925[[#This Row],[NETO]]*2% -> 0
T7: =S7/1.19 -> 0 | U7: =Tabla141925[[#This Row],[NETO]]*2% -> 0
T8: =S8/1.19 -> 0 | U8: =Tabla141925[[#This Row],[NETO]]*2% -> 0
T9: =S9/1.19 -> 0 | U9: =Tabla141925[[#This Row],[NETO]]*2% -> 0
T10: =S10/1.19 -> 0 | U10: =Tabla141925[[#This Row],[NETO]]*2% -> 0 | Z10: =SUM(Z2:Z9) -> 0
T11: =S11/1.19 -> 0 | U11: =Tabla141925[[#This Row],[NETO]]*2% -> 0
T12: =S12/1.19 -> 0 | U12: =Tabla141925[[#This Row],[NETO]]*2% -> 0
T13: =S13/1.19 -> 0 | U13: =Tabla141925[[#This Row],[NETO]]*2% -> 0
T14: =S14/1.19 -> 0 | U14: =Tabla141925[[#This Row],[NETO]]*2% -> 0
T15: =S15/1.19 -> 0 | U15: =Tabla141925[[#This Row],[NETO]]*2% -> 0
T16: =S16/1.19 -> 0 | U16: =Tabla141925[[#This Row],[NETO]]*2% -> 0
T17: =S17/1.19 -> 0 | U17: =Tabla141925[[#This Row],[NETO]]*2% -> 0
T18: =S18/1.19 -> 0 | U18: =Tabla141925[[#This Row],[NETO]]*2% -> 0
T19: =S19/1.19 -> 0 | U19: =Tabla141925[[#This Row],[NETO]]*2% -> 0
T20: =S20/1.19 -> 0 | U20: =Tabla141925[[#This Row],[NETO]]*2% -> 0
T21: =S21/1.19 -> 0 | U21: =Tabla141925[[#This Row],[NETO]]*2% -> 0
T22: =S22/1.19 -> 0 | U22: =Tabla141925[[#This Row],[NETO]]*2% -> 0
... T49: =S49/1.19 -> 0 | U49: =Tabla141925[[#This Row],[NETO]]*2% -> 0
A50: TOTAL | B50: =COUNT(B3:B49) -> 0 | S50: =SUM(S3:S49) -> 0 | T50: =SUM(T3:T49) -> 0 | U50: =Tabla141925[[#This Row],[NETO]]*2% -> 0

Sheet MAYO
C1: CLIENTE | G1: VEHICULO | M1: TRABAJO | R1: DATOS DE PAGO | X1: OT | Y1: PRODUCTO | Z1: COMISION
A2: FECHA | B2: OT | C2: NOMBRE | D2: RUT | E2: FONO | F2: CORREO | G2: MARCA | H2: MODELO | I2: KILOMETROS | J2: AÑO | K2: COLOR | L2: PATENTE | M2: ESCAPE | N2: REPRO | O2: IMPORT. | P2: OTROS | Q2: DETALLE | R2: RESERVA $25,000 | S2: TOTAL | T2: NETO | U2: COMISION
T3: =S3/1.19 -> 0 | U3: =Tabla14[[#This Row],[NETO]]*2% -> 0
T4: =S4/1.19 -> 0 | U4: =Tabla14[[#This Row],[NETO]]*2% -> 0
T5: =S5/1.19 -> 0 | U5: =Tabla14[[#This Row],[NETO]]*2% -> 0
T6: =S6/1.19 -> 0 | U6: =Tabla14[[#This Row],[NETO]]*2% -> 0
T7: =S7/1.19 -> 0 | U7: =Tabla14[[#This Row],[NETO]]*2% -> 0
T8: =S8/1.19 -> 0 | U8: =Tabla14[[#This Row],[NETO]]*2% -> 0
T9: =S9/1.19 -> 0 | U9: =Tabla14[[#This Row],[NETO]]*2% -> 0
T10: =S10/1.19 -> 0 | U10: =Tabla14[[#This Row],[NETO]]*2% -> 0 | Z10: =SUM(Z2:Z9) -> 0
T11: =S11/1.19 -> 0 | U11: =Tabla14[[#This Row],[NETO]]*2% -> 0
T12: =S12/1.19 -> 0 | U12: =Tabla14[[#This Row],[NETO]]*2% -> 0
T13: =S13/1.19 -> 0 | U13: =Tabla14[[#This Row],[NETO]]*2% -> 0
T14: =S14/1.19 -> 0 | U14: =Tabla14[[#This Row],[NETO]]*2% -> 0
T15: =S15/1.19 -> 0 | U15: =Tabla14[[#This Row],[NETO]]*2% -> 0
T16: =S16/1.19 -> 0 | U16: =Tabla14[[#This Row],[NETO]]*2% -> 0
T17: =S17/1.19 -> 0 | U17: =Tabla14[[#This Row],[NETO]]*2% -> 0
T18: =S18/1.19 -> 0 | U18: =Tabla14[[#This Row],[NETO]]*2% -> 0
T19: =S19/1.19 -> 0 | U19: =Tabla14[[#This Row],[NETO]]*2% -> 0
T20: =S20/1.19 -> 0 | U20: =Tabla14[[#This Row],[NETO]]*2% -> 0
T21: =S21/1.19 -> 0 | U21: =Tabla14[[#This Row],[NETO]]*2% -> 0
T22: =S22/1.19 -> 0 | U22: =Tabla14[[#This Row],[NETO]]*2% -> 0
... T49: =S49/1.19 -> 0 | U49: =Tabla14[[#This Row],[NETO]]*2% -> 0
A50: TOTAL | B50: =COUNT(B3:B49) -> 0 | S50: =SUM(S3:S49) -> 0 | T50: =SUM(T3:T49) -> 0 | U50: =Tabla14[[#This Row],[NETO]]*2% -> 0

Sheet JUNIO
C1: CLIENTE | G1: VEHICULO | M1: TRABAJO | R1: DATOS DE PAGO | X1: OT | Y1: PRODUCTO | Z1: COMISION
A2: FECHA | B2: OT | C2: NOMBRE | D2: RUT | E2: FONO | F2: CORREO | G2: MARCA | H2: MODELO | I2: KILOMETROS | J2: AÑO | K2: COLOR | L2: PATENTE | M2: ESCAPE | N2: REPRO | O2: IMPORT. | P2: OTROS | Q2: DETALLE | R2: RESERVA $25,000 | S2: TOTAL | T2: NETO | U2: COMISION
T3: =S3/1.19 -> 0 | U3: =Tabla146[[#This Row],[NETO]]*2% -> 0
T4: =S4/1.19 -> 0 | U4: =Tabla146[[#This Row],[NETO]]*2% -> 0
T5: =S5/1.19 -> 0 | U5: =Tabla146[[#This Row],[NETO]]*2% -> 0
T6: =S6/1.19 -> 0 | U6: =Tabla146[[#This Row],[NETO]]*2% -> 0
T7: =S7/1.19 -> 0 | U7: =Tabla146[[#This Row],[NETO]]*2% -> 0
T8: =S8/1.19 -> 0 | U8: =Tabla146[[#This Row],[NETO]]*2% -> 0
T9: =S9/1.19 -> 0 | U9: =Tabla146[[#This Row],[NETO]]*2% -> 0
T10: =S10/1.19 -> 0 | U10: =Tabla146[[#This Row],[NETO]]*2% -> 0 | Z10: =SUM(Z2:Z9) -> 0
T11: =S11/1.19 -> 0 | U11: =Tabla146[[#This Row],[NETO]]*2% -> 0
T12: =S12/1.19 -> 0 | U12: =Tabla146[[#This Row],[NETO]]*2% -> 0
T13: =S13/1.19 -> 0 | U13: =Tabla146[[#This Row],[NETO]]*2% -> 0
T14: =S14/1.19 -> 0 | U14: =Tabla146[[#This Row],[NETO]]*2% -> 0
T15: =S15/1.19 -> 0 | U15: =Tabla146[[#This Row],[NETO]]*2% -> 0
T16: =S16/1.19 -> 0 | U16: =Tabla146[[#This Row],[NETO]]*2% -> 0
T17: =S17/1.19 -> 0 | U17: =Tabla146[[#This Row],[NETO]]*2% -> 0
T18: =S18/1.19 -> 0 | U18: =Tabla146[[#This Row],[NETO]]*2% -> 0
T19: =S19/1.19 -> 0 | U19: =Tabla146[[#This Row],[NETO]]*2% -> 0
T20: =S20/1.19 -> 0 | U20: =Tabla146[[#This Row],[NETO]]*2% -> 0
T21: =S21/1.19 -> 0 | U21: =Tabla146[[#This Row],[NETO]]*2% -> 0
T22: =S22/1.19 -> 0 | U22: =Tabla146[[#This Row],[NETO]]*2% -> 0
T23: 0 | U23: 0
T24: =S24/1.19 -> 0 | U24: =Tabla146[[#This Row],[NETO]]*2% -> 0
T25: =S25/1.19 -> 0 | U25: =Tabla146[[#This Row],[NETO]]*2% -> 0
T26: =S26/1.19 -> 0 | U26: =Tabla146[[#This Row],[NETO]]*2% -> 0
T27: =S27/1.19 -> 0 | U27: =Tabla146[[#This Row],[NETO]]*2% -> 0
T28: =S28/1.19 -> 0 | U28: =Tabla146[[#This Row],[NETO]]*2% -> 0
T29: =S29/1.19 -> 0 | U29: =Tabla146[[#This Row],[NETO]]*2% -> 0
T30: =S30/1.19 -> 0 | U30: =Tabla146[[#This Row],[NETO]]*2% -> 0
T31: =S31/1.19 -> 0 | U31: =Tabla146[[#This Row],[NETO]]*2% -> 0
T32: =S32/1.19 -> 0 | U32: =Tabla146[[#This Row],[NETO]]*2% -> 0
T33: =S33/1.19 -> 0 | U33: =Tabla146[[#This Row],[NETO]]*2% -> 0
T34: =S34/1.19 -> 0 | U34: =Tabla146[[#This Row],[NETO]]*2% -> 0
T35: =S35/1.19 -> 0 | U35: =Tabla146[[#This Row],[NETO]]*2% -> 0
... T51: =S51/1.19 -> 0 | U51: =Tabla146[[#This Row],[NETO]]*2% -> 0
A52: TOTAL | B52: =COUNT(B3:B51) -> 0 | S52: =SUM(S3:S51) -> 0 | T52: =SUM(T3:T51) -> 0 | U52: =Tabla146[[#This Row],[NETO]]*2% -> 0

Sheet JULIO
C1: CLIENTE | G1: VEHICULO | M1: TRABAJO | R1: DATOS DE PAGO | X1: OT | Y1: PRODUCTO | Z1: COMISION
A2: FECHA | B2: OT | C2: NOMBRE | D2: RUT | E2: FONO | F2: CORREO | G2: MARCA | H2: MODELO | I2: KILOMETROS | J2: AÑO | K2: COLOR | L2: PATENTE | M2: ESCAPE | N2: REPRO | O2: IMPORT. | P2: OTROS | Q2: DETALLE | R2: RESERVA $25,000 | S2: TOTAL | T2: NETO | U2: COMISION
T3: =Tabla1462[[#This Row],[TOTAL]]/1.19 -> 0 | U3: =Tabla1462[[#This Row],[NETO]]*2% -> 0
T4: =Tabla1462[[#This Row],[TOTAL]]/1.19 -> 0 | U4: =Tabla1462[[#This Row],[NETO]]*2% -> 0
T5: =Tabla1462[[#This Row],[TOTAL]]/1.19 -> 0 | U5: =Tabla1462[[#This Row],[NETO]]*2% -> 0
T6: =Tabla1462[[#This Row],[TOTAL]]/1.19 -> 0 | U6: =Tabla1462[[#This Row],[NETO]]*2% -> 0
T7: =Tabla1462[[#This Row],[TOTAL]]/1.19 -> 0 | U7: =Tabla1462[[#This Row],[NETO]]*2% -> 0
T8: =Tabla1462[[#This Row],[TOTAL]]/1.19 -> 0 | U8: =Tabla1462[[#This Row],[NETO]]*2% -> 0
T9: =Tabla1462[[#This Row],[TOTAL]]/1.19 -> 0 | U9: =Tabla1462[[#This Row],[NETO]]*2% -> 0
T10: =Tabla1462[[#This Row],[TOTAL]]/1.19 -> 0 | U10: =Tabla1462[[#This Row],[NETO]]*2% -> 0
T11: =Tabla1462[[#This Row],[TOTAL]]/1.19 -> 0 | U11: =Tabla1462[[#This Row],[NETO]]*2% -> 0
T12: =Tabla1462[[#This Row],[TOTAL]]/1.19 -> 0 | U12: =Tabla1462[[#This Row],[NETO]]*2% -> 0
T13: =Tabla1462[[#This Row],[TOTAL]]/1.19 -> 0 | U13: =Tabla1462[[#This Row],[NETO]]*2% -> 0
T14: =Tabla1462[[#This Row],[TOTAL]]/1.19 -> 0 | U14: =Tabla1462[[#This Row],[NETO]]*2% -> 0
... T47: =Tabla1462[[#This Row],[TOTAL]]/1.19 -> 0 | U47: =Tabla1462[[#This Row],[NETO]]*2% -> 0
T48: =S48/1.19 -> 0 | U48: =Tabla1462[[#This Row],[NETO]]*2% -> 0
T49: =S49/1.19 -> 0 | U49: =Tabla1462[[#This Row],[NETO]]*2% -> 0
T50: =S50/1.19 -> 0 | U50: =Tabla1462[[#This Row],[NETO]]*2% -> 0
T51: =S51/1.19 -> 0 | U51: =Tabla1462[[#This Row],[NETO]]*2% -> 0
T52: =S52/1.19 -> 0 | U52: =Tabla1462[[#This Row],[NETO]]*2% -> 0
T53: =S53/1.19 -> 0 | U53: =Tabla1462[[#This Row],[NETO]]*2% -> 0
T54: =S54/1.19 -> 0 | U54: =Tabla1462[[#This Row],[NETO]]*2% -> 0
T55: =S55/1.19 -> 0 | U55: =Tabla1462[[#This Row],[NETO]]*2% -> 0
T56: =S56/1.19 -> 0 | U56: =Tabla1462[[#This Row],[NETO]]*2% -> 0
T57: =S57/1.19 -> 0 | U57: =Tabla1462[[#This Row],[NETO]]*2% -> 0
T58: =S58/1.19 -> 0 | U58: =Tabla1462[[#This Row],[NETO]]*2% -> 0
T59: =Tabla1462[[#This Row],[TOTAL]]/1.19 -> 0 | U59: =Tabla1462[[#This Row],[NETO]]*2% -> 0
A60: TOTAL | B60: =COUNT(B3:B59) -> 0 | S60: =SUM(S3:S59) -> 0 | T60: =SUM(T3:T59) -> 0 | U60: =Tabla1462[[#This Row],[NETO]]*2% -> 0

Sheet AGOSTO
C1: CLIENTE | G1: VEHICULO | M1: TRABAJO | R1: DATOS DE PAGO | X1: OT | Y1: PRODUCTO | Z1: COMISION
A2: FECHA | B2: OT | C2: NOMBRE | D2: RUT | E2: FONO | F2: CORREO | G2: MARCA | H2: MODELO | I2: KILOMETROS | J2: AÑO | K2: COLOR | L2: PATENTE | M2: ESCAPE | N2: REPRO | O2: IMPORT. | P2: OTROS | Q2: DETALLE | R2: RESERVA $25,000 | S2: TOTAL | T2: NETO | U2: COMISION
T3: =Tabla14628[[#This Row],[TOTAL]]/1.19 -> 0 | U3: =Tabla14628[[#This Row],[NETO]]*2% -> 0
T4: =Tabla14628[[#This Row],[TOTAL]]/1.19 -> 0 | U4: =Tabla14628[[#This Row],[NETO]]*2% -> 0
T5: =Tabla14628[[#This Row],[TOTAL]]/1.19 -> 0 | U5: =Tabla14628[[#This Row],[NETO]]*2% -> 0
T6: =Tabla14628[[#This Row],[TOTAL]]/1.19 -> 0 | U6: =Tabla14628[[#This Row],[NETO]]*2% -> 0
T7: =Tabla14628[[#This Row],[TOTAL]]/1.19 -> 0 | U7: =Tabla14628[[#This Row],[NETO]]*2% -> 0
T8: =Tabla14628[[#This Row],[TOTAL]]/1.19 -> 0 | U8: =Tabla14628[[#This Row],[NETO]]*2% -> 0
T9: =Tabla14628[[#This Row],[TOTAL]]/1.19 -> 0 | U9: =Tabla14628[[#This Row],[NETO]]*2% -> 0
T10: =Tabla14628[[#This Row],[TOTAL]]/1.19 -> 0 | U10: =Tabla14628[[#This Row],[NETO]]*2% -> 0
T11: =Tabla14628[[#This Row],[TOTAL]]/1.19 -> 0 | U11: =Tabla14628[[#This Row],[NETO]]*2% -> 0
T12: =Tabla14628[[#This Row],[TOTAL]]/1.19 -> 0 | U12: =Tabla14628[[#This Row],[NETO]]*2% -> 0
T13: =Tabla14628[[#This Row],[TOTAL]]/1.19 -> 0 | U13: =Tabla14628[[#This Row],[NETO]]*2% -> 0
T14: =Tabla14628[[#This Row],[TOTAL]]/1.19 -> 0 | U14: =Tabla14628[[#This Row],[NETO]]*2% -> 0
... T47: =Tabla14628[[#This Row],[TOTAL]]/1.19 -> 0 | U47: =Tabla14628[[#This Row],[NETO]]*2% -> 0
T48: =S48/1.19 -> 0 | U48: =Tabla14628[[#This Row],[NETO]]*2% -> 0
T49: =S49/1.19 -> 0 | U49: =Tabla14628[[#This Row],[NETO]]*2% -> 0
T50: =S50/1.19 -> 0 | U50: =Tabla14628[[#This Row],[NETO]]*2% -> 0
T51: =S51/1.19 -> 0 | U51: =Tabla14628[[#This Row],[NETO]]*2% -> 0
T52: =S52/1.19 -> 0 | U52: =Tabla14628[[#This Row],[NETO]]*2% -> 0
A53: TOTAL | B53: =COUNT(B3:B52) -> 0 | S53: =SUM(S3:S52) -> 0 | T53: =SUM(T3:T52) -> 0 | U53: =Tabla14628[[#This Row],[NETO]]*2% -> 0

Sheet SEPTIEMBRE
C1: CLIENTE | G1: VEHICULO | M1: TRABAJO | R1: DATOS DE PAGO | X1: OT | Y1: PRODUCTO | Z1: COMISION
A2: FECHA | B2: OT | C2: NOMBRE | D2: RUT | E2: FONO | F2: CORREO | G2: MARCA | H2: MODELO | I2: KILOMETROS | J2: AÑO | K2: COLOR | L2: PATENTE | M2: ESCAPE | N2: REPRO | O2: IMPORT. | P2: OTROS | Q2: DETALLE | R2: RESERVA $25,000 | S2: TOTAL | T2: NETO | U2: COMISION
T3: =Tabla1462827[[#This Row],[TOTAL]]/1.19 -> 0 | U3: =Tabla1462827[[#This Row],[NETO]]*2% -> 0
T4: =Tabla1462827[[#This Row],[TOTAL]]/1.19 -> 0 | U4: =Tabla1462827[[#This Row],[NETO]]*2% -> 0
T5: =Tabla1462827[[#This Row],[TOTAL]]/1.19 -> 0 | U5: =Tabla1462827[[#This Row],[NETO]]*2% -> 0
T6: =Tabla1462827[[#This Row],[TOTAL]]/1.19 -> 0 | U6: =Tabla1462827[[#This Row],[NETO]]*2% -> 0
T7: =Tabla1462827[[#This Row],[TOTAL]]/1.19 -> 0 | U7: =Tabla1462827[[#This Row],[NETO]]*2% -> 0
T8: =Tabla1462827[[#This Row],[TOTAL]]/1.19 -> 0 | U8: =Tabla1462827[[#This Row],[NETO]]*2% -> 0
T9: =Tabla1462827[[#This Row],[TOTAL]]/1.19 -> 0 | U9: =Tabla1462827[[#This Row],[NETO]]*2% -> 0
T10: =Tabla1462827[[#This Row],[TOTAL]]/1.19 -> 0 | U10: =Tabla1462827[[#This Row],[NETO]]*2% -> 0
T11: =Tabla1462827[[#This Row],[TOTAL]]/1.19 -> 0 | U11: =Tabla1462827[[#This Row],[NETO]]*2% -> 0
T12: =Tabla1462827[[#This Row],[TOTAL]]/1.19 -> 0 | U12: =Tabla1462827[[#This Row],[NETO]]*2% -> 0
T13: =Tabla1462827[[#This Row],[TOTAL]]/1.19 -> 0 | U13: =Tabla1462827[[#This Row],[NETO]]*2% -> 0
T14: =Tabla1462827[[#This Row],[TOTAL]]/1.19 -> 0 | U14: =Tabla1462827[[#This Row],[NETO]]*2% -> 0
... T47: =Tabla1462827[[#This Row],[TOTAL]]/1.19 -> 0 | U47: =Tabla1462827[[#This Row],[NETO]]*2% -> 0
T48: =S48/1.19 -> 0 | U48: =Tabla1462827[[#This Row],[NETO]]*2% -> 0
T49: =S49/1.19 -> 0 | U49: =Tabla1462827[[#This Row],[NETO]]*2% -> 0
T50: =S50/1.19 -> 0 | U50: =Tabla1462827[[#This Row],[NETO]]*2% -> 0
T51: =S51/1.19 -> 0 | U51: =Tabla1462827[[#This Row],[NETO]]*2% -> 0
T52: =S52/1.19 -> 0 | U52: =Tabla1462827[[#This Row],[NETO]]*2% -> 0
A53: TOTAL | B53: =COUNT(B3:B52) -> 0 | S53: =SUM(S3:S52) -> 0 | T53: =SUM(T3:T52) -> 0 | U53: =Tabla1462827[[#This Row],[NETO]]*2% -> 0

Sheet OCTUBRE
C1: CLIENTE | G1: VEHICULO | M1: TRABAJO | R1: DATOS DE PAGO | X1: OT | Y1: PRODUCTO | Z1: COMISION | AA1: Columna1
A2: FECHA | B2: OT | C2: NOMBRE | D2: RUT | E2: FONO | F2: CORREO | G2: MARCA | H2: MODELO | I2: KILOMETROS | J2: AÑO | K2: COLOR | L2: PATENTE | M2: ESCAPE | N2: REPRO | O2: IMPORT. | P2: OTROS | Q2: DETALLE | R2: RESERVA $25,000 | S2: TOTAL | T2: NETO | U2: COMISION | AD2: COMISIONES | AF2: VIATICOS | AG2: TOTAL
T3: =Tabla146281012[[#This Row],[TOTAL]]/1.19 -> 0 | U3: =Tabla146281012[[#This Row],[NETO]]*2% -> 0 | AD3: OCTUBRE | AE3: 822642 | AF3: 402268 | AG3: =AE3-AF3 -> 420374
T4: =Tabla146281012[[#This Row],[TOTAL]]/1.19 -> 0 | U4: =Tabla146281012[[#This Row],[NETO]]*2% -> 0
T5: =Tabla146281012[[#This Row],[TOTAL]]/1.19 -> 0 | U5: =Tabla146281012[[#This Row],[NETO]]*2% -> 0
T6: =Tabla146281012[[#This Row],[TOTAL]]/1.19 -> 0 | U6: =Tabla146281012[[#This Row],[NETO]]*2% -> 0
T7: =Tabla146281012[[#This Row],[TOTAL]]/1.19 -> 0 | U7: =Tabla146281012[[#This Row],[NETO]]*2% -> 0
T8: =Tabla146281012[[#This Row],[TOTAL]]/1.19 -> 0 | U8: =Tabla146281012[[#This Row],[NETO]]*2% -> 0
T9: =Tabla146281012[[#This Row],[TOTAL]]/1.19 -> 0 | U9: =Tabla146281012[[#This Row],[NETO]]*2% -> 0
T10: =Tabla146281012[[#This Row],[TOTAL]]/1.19 -> 0 | U10: =Tabla146281012[[#This Row],[NETO]]*2% -> 0
T11: =Tabla146281012[[#This Row],[TOTAL]]/1.19 -> 0 | U11: =Tabla146281012[[#This Row],[NETO]]*2% -> 0
T12: =Tabla146281012[[#This Row],[TOTAL]]/1.19 -> 0 | U12: =Tabla146281012[[#This Row],[NETO]]*2% -> 0
T13: =Tabla146281012[[#This Row],[TOTAL]]/1.19 -> 0 | U13: =Tabla146281012[[#This Row],[NETO]]*2% -> 0
T14: =Tabla146281012[[#This Row],[TOTAL]]/1.19 -> 0 | U14: =Tabla146281012[[#This Row],[NETO]]*2% -> 0
T15: =Tabla146281012[[#This Row],[TOTAL]]/1.19 -> 0 | U15: =Tabla146281012[[#This Row],[NETO]]*2% -> 0
... T47: =Tabla146281012[[#This Row],[TOTAL]]/1.19 -> 0 | U47: =Tabla146281012[[#This Row],[NETO]]*2% -> 0
T48: =S48/1.19 -> 0 | U48: =Tabla146281012[[#This Row],[NETO]]*2% -> 0
T49: =S49/1.19 -> 0 | U49: =Tabla146281012[[#This Row],[NETO]]*2% -> 0
T50: =S50/1.19 -> 0 | U50: =Tabla146281012[[#This Row],[NETO]]*2% -> 0
T51: =S51/1.19 -> 0 | U51: =Tabla146281012[[#This Row],[NETO]]*2% -> 0
T52: =S52/1.19 -> 0 | U52: =Tabla146281012[[#This Row],[NETO]]*2% -> 0
T53: =S53/1.19 -> 0 | U53: =Tabla146281012[[#This Row],[NETO]]*2% -> 0
T54: =S54/1.19 -> 0 | U54: =Tabla146281012[[#This Row],[NETO]]*2% -> 0
T55: =S55/1.19 -> 0 | U55: =Tabla146281012[[#This Row],[NETO]]*2% -> 0
T56: =S56/1.19 -> 0 | U56: =Tabla146281012[[#This Row],[NETO]]*2% -> 0
T57: =S57/1.19 -> 0 | U57: =Tabla146281012[[#This Row],[NETO]]*2% -> 0
T58: =S58/1.19 -> 0 | U58: =Tabla146281012[[#This Row],[NETO]]*2% -> 0
T59: =S59/1.19 -> 0 | U59: =Tabla146281012[[#This Row],[NETO]]*2% -> 0
... T71: =S71/1.19 -> 0 | U71: =Tabla146281012[[#This Row],[NETO]]*2% -> 0
A72: TOTAL | B72: =COUNT(B3:B68) -> 0 | S72: =SUM(S3:S71) -> 0 | T72: =SUM(T3:T71) -> 0 | U72: =Tabla146281012[[#This Row],[NETO]]*2%+Z2+Z3 -> 0
S82: ¡'

Sheet NOVIEMBRE
C1: CLIENTE | G1: VEHICULO | M1: TRABAJO | R1: DATOS DE PAGO | W1: OT | X1: PRODUCTO | Y1: COMISION
A2: FECHA | B2: OT | C2: NOMBRE | D2: RUT | E2: FONO | F2: CORREO | G2: MARCA | H2: MODELO | I2: KILOMETROS | J2: AÑO | K2: COLOR | L2: PATENTE | M2: ESCAPE | N2: REPRO | O2: IMPORT. | P2: OTROS | Q2: DETALLE | R2: RESERVA $25,000 | S2: TOTAL | T2: NETO | U2: COMISION
T3: =Tabla14628101214[[#This Row],[TOTAL]]/1.19 -> 0 | U3: =Tabla14628101214[[#This Row],[NETO]]*2% -> 0
T4: =Tabla14628101214[[#This Row],[TOTAL]]/1.19 -> 0 | U4: =Tabla14628101214[[#This Row],[NETO]]*2% -> 0
T5: =Tabla14628101214[[#This Row],[TOTAL]]/1.19 -> 0 | U5: =Tabla14628101214[[#This Row],[NETO]]*2% -> 0
T6: =Tabla14628101214[[#This Row],[TOTAL]]/1.19 -> 0 | U6: =Tabla14628101214[[#This Row],[NETO]]*2% -> 0
T7: =Tabla14628101214[[#This Row],[TOTAL]]/1.19 -> 0 | U7: =Tabla14628101214[[#This Row],[NETO]]*2% -> 0
T8: =Tabla14628101214[[#This Row],[TOTAL]]/1.19 -> 0 | U8: =Tabla14628101214[[#This Row],[NETO]]*2% -> 0
T9: =Tabla14628101214[[#This Row],[TOTAL]]/1.19 -> 0 | U9: =Tabla14628101214[[#This Row],[NETO]]*2% -> 0
T10: =Tabla14628101214[[#This Row],[TOTAL]]/1.19 -> 0 | U10: =Tabla14628101214[[#This Row],[NETO]]*2% -> 0
T11: =Tabla14628101214[[#This Row],[TOTAL]]/1.19 -> 0 | U11: =Tabla14628101214[[#This Row],[NETO]]*2% -> 0
T12: =Tabla14628101214[[#This Row],[TOTAL]]/1.19 -> 0 | U12: =Tabla14628101214[[#This Row],[NETO]]*2% -> 0
T13: =Tabla14628101214[[#This Row],[TOTAL]]/1.19 -> 0 | U13: =Tabla14628101214[[#This Row],[NETO]]*2% -> 0
T14: =Tabla14628101214[[#This Row],[TOTAL]]/1.19 -> 0 | U14: =Tabla14628101214[[#This Row],[NETO]]*2% -> 0
... T47: =Tabla14628101214[[#This Row],[TOTAL]]/1.19 -> 0 | U47: =Tabla14628101214[[#This Row],[NETO]]*2% -> 0
T48: =S48/1.19 -> 0 | U48: =Tabla14628101214[[#This Row],[NETO]]*2% -> 0
T49: =S49/1.19 -> 0 | U49: =Tabla14628101214[[#This Row],[NETO]]*2% -> 0
T50: =S50/1.19 -> 0 | U50: =Tabla14628101214[[#This Row],[NETO]]*2% -> 0
T51: =S51/1.19 -> 0 | U51: =Tabla14628101214[[#This Row],[NETO]]*2% -> 0
T52: =S52/1.19 -> 0 | U52: =Tabla14628101214[[#This Row],[NETO]]*2% -> 0
T53: =S53/1.19 -> 0 | U53: =Tabla14628101214[[#This Row],[NETO]]*2% -> 0
T54: =S54/1.19 -> 0 | U54: =Tabla14628101214[[#This Row],[NETO]]*2% -> 0
T55: =S55/1.19 -> 0 | U55: =Tabla14628101214[[#This Row],[NETO]]*2% -> 0
T56: =S56/1.19 -> 0 | U56: =Tabla14628101214[[#This Row],[NETO]]*2% -> 0 | Y56: COMISIONES | AA56: VIATICOS | AB56: TOTAL
T57: =S57/1.19 -> 0 | U57: =Tabla14628101214[[#This Row],[NETO]]*2% -> 0 | Y57: NOVIEMBRE | Z57: 443710 | AA57: 402268 | AB57: =Z57-AA57 -> 41442
T58: =S58/1.19 -> 0 | U58: =Tabla14628101214[[#This Row],[NETO]]*2% -> 0
T59: =S59/1.19 -> 0 | U59: =Tabla14628101214[[#This Row],[NETO]]*2% -> 0
A60: TOTAL | B60: =COUNT(B3:B59) -> 0 | S60: =SUM(S3:S59) -> 0 | T60: =SUM(T3:T59) -> 0 | U60: =Tabla14628101214[[#This Row],[NETO]]*2% -> 0

Sheet DICIEMBRE
C1: CLIENTE | G1: VEHICULO | M1: TRABAJO | R1: DATOS DE PAGO | X1: OT | Y1: PRODUCTO | Z1: COMISION
A2: FECHA | B2: OT | C2: NOMBRE | D2: RUT | E2: FONO | F2: CORREO | G2: MARCA | H2: MODELO | I2: KILOMETROS | J2: AÑO | K2: COLOR | L2: PATENTE | M2: ESCAPE | N2: REPRO | O2: IMPORT. | P2: OTROS | Q2: DETALLE | R2: RESERVA $25,000 | S2: TOTAL | T2: NETO | U2: COMISION
T3: =Tabla1462810121416[[#This Row],[TOTAL]]/1.19 -> 0 | U3: =Tabla1462810121416[[#This Row],[NETO]]*2% -> 0
T4: =Tabla1462810121416[[#This Row],[TOTAL]]/1.19 -> 0 | U4: =Tabla1462810121416[[#This Row],[NETO]]*2% -> 0
T5: =Tabla1462810121416[[#This Row],[TOTAL]]/1.19 -> 0 | U5: =Tabla1462810121416[[#This Row],[NETO]]*2% -> 0
T6: =Tabla1462810121416[[#This Row],[TOTAL]]/1.19 -> 0 | U6: =Tabla1462810121416[[#This Row],[NETO]]*2% -> 0
T7: =Tabla1462810121416[[#This Row],[TOTAL]]/1.19 -> 0 | U7: =Tabla1462810121416[[#This Row],[NETO]]*2% -> 0
T8: =Tabla1462810121416[[#This Row],[TOTAL]]/1.19 -> 0 | U8: =Tabla1462810121416[[#This Row],[NETO]]*2% -> 0
T9: =Tabla1462810121416[[#This Row],[TOTAL]]/1.19 -> 0 | U9: =Tabla1462810121416[[#This Row],[NETO]]*2% -> 0
T10: =Tabla1462810121416[[#This Row],[TOTAL]]/1.19 -> 0 | U10: =Tabla1462810121416[[#This Row],[NETO]]*2% -> 0
T11: =Tabla1462810121416[[#This Row],[TOTAL]]/1.19 -> 0 | U11: =Tabla1462810121416[[#This Row],[NETO]]*2% -> 0
T12: =Tabla1462810121416[[#This Row],[TOTAL]]/1.19 -> 0 | U12: =Tabla1462810121416[[#This Row],[NETO]]*2% -> 0
T13: =Tabla1462810121416[[#This Row],[TOTAL]]/1.19 -> 0 | U13: =Tabla1462810121416[[#This Row],[NETO]]*2% -> 0
T14: =Tabla1462810121416[[#This Row],[TOTAL]]/1.19 -> 0 | U14: =Tabla1462810121416[[#This Row],[NETO]]*2% -> 0
... T47: =Tabla1462810121416[[#This Row],[TOTAL]]/1.19 -> 0 | U47: =Tabla1462810121416[[#This Row],[NETO]]*2% -> 0
T48: =S48/1.19 -> 0 | U48: =Tabla1462810121416[[#This Row],[NETO]]*2% -> 0
T49: =S49/1.19 -> 0 | U49: =Tabla1462810121416[[#This Row],[NETO]]*2% -> 0
T50: =S50/1.19 -> 0 | U50: =Tabla1462810121416[[#This Row],[NETO]]*2% -> 0
T51: =S51/1.19 -> 0 | U51: =Tabla1462810121416[[#This Row],[NETO]]*2% -> 0
T52: =S52/1.19 -> 0 | U52: =Tabla1462810121416[[#This Row],[NETO]]*2% -> 0
T53: =S53/1.19 -> 0 | U53: =Tabla1462810121416[[#This Row],[NETO]]*2% -> 0
T54: =S54/1.19 -> 0 | U54: =Tabla1462810121416[[#This Row],[NETO]]*2% -> 0
T55: =S55/1.19 -> 0 | U55: =Tabla1462810121416[[#This Row],[NETO]]*2% -> 0
T56: =S56/1.19 -> 0 | U56: =Tabla1462810121416[[#This Row],[NETO]]*2% -> 0
T57: =S57/1.19 -> 0 | U57: =Tabla1462810121416[[#This Row],[NETO]]*2% -> 0
T58: =S58/1.19 -> 0 | U58: =Tabla1462810121416[[#This Row],[NETO]]*2% -> 0
T59: =S59/1.19 -> 0 | U59: =Tabla1462810121416[[#This Row],[NETO]]*2% -> 0
... T64: =S64/1.19 -> 0 | U64: =Tabla1462810121416[[#This Row],[NETO]]*2% -> 0
A65: TOTAL | B65: =COUNT(B3:B62) -> 0 | S65: =SUM(S3:S64) -> 0 | T65: =SUM(T3:T64) -> 0 | U65: =Tabla1462810121416[[#This Row],[NETO]]*2%+Z2 -> 0

Sheet VENTAS 2026
A1: MES | B1: OT | C1: VENTA NETA
A2: ENERO | B2: =ENERO!B77 -> 47 | C2: =ENERO!T87 -> 0
A3: FEBRERO | B3: =FEBRERO!B50 -> 28 | C3: =FEBRERO!T60 -> 0
A4: MARZO | B4: =MARZO!B50 -> 45 | C4: =MARZO!T60 -> 0
A5: ABRIL | B5: =ABRIL!B50 -> 0 | C5: =ABRIL!T60 -> 0
A6: MAYO | B6: =MAYO!B50 -> 0 | C6: =MAYO!T50 -> 0
A7: JUNIO | B7: =JUNIO!B52 -> 0 | C7: =JUNIO!T52 -> 0
A8: JULIO | B8: =JULIO!B60 -> 0 | C8: =JULIO!T60 -> 0
A9: AGOSTO | B9: =AGOSTO!B53 -> 0 | C9: =AGOSTO!T53 -> 0
A10: SEPTIEMBRE | B10: =SEPTIEMBRE!B66 -> 0 | C10: =SEPTIEMBRE!T66 -> 0
A11: OCTUBRE | B11: =OCTUBRE!B72 -> 0 | C11: =OCTUBRE!T72 -> 0
A12: NOVIEMBRE | B12: =NOVIEMBRE!B60 -> 0 | C12: =NOVIEMBRE!T60 -> 0
A13: DICIEMBRE | B13: =DICIEMBRE!B65 -> 0 | C13: =DICIEMBRE!T65 -> 0
A14: TOTAL | C14: =SUM(C2:C13) -> 0
